<?xml version="1.0" encoding="UTF-8"?>
<!-- Generated by org.testng.reporters.JUnitXMLReporter -->
<testsuite hostname="IS54" ignored="0" name="Default test" tests="1" failures="1" timestamp="01 Nov 2018 01:41:59 GMT" time="65.153" errors="0">
  <testcase name="testB" time="62.175" classname="com.datadriven.frame.testcases.DummyTestB">
    <failure type="java.lang.AssertionError" message="Test Failed">
      <![CDATA[java.lang.AssertionError: Test Failed
	at org.testng.Assert.fail(Assert.java:94)
	at com.datadriven.frame.base.BaseTest.reportFailure(BaseTest.java:218)
	at com.datadriven.frame.testcases.DummyTestB.testB(DummyTestB.java:105)
	at sun.reflect.NativeMethodAccessorImpl.invoke0(Native Method)
	at sun.reflect.NativeMethodAccessorImpl.invoke(Unknown Source)
	at sun.reflect.DelegatingMethodAccessorImpl.invoke(Unknown Source)
	at java.lang.reflect.Method.invoke(Unknown Source)
	at org.testng.internal.MethodInvocationHelper.invokeMethod(MethodInvocationHelper.java:104)
	at org.testng.internal.Invoker.invokeMethod(Invoker.java:645)
	at org.testng.internal.Invoker.invokeTestMethod(Invoker.java:851)
	at org.testng.internal.TestMethodWithDataProviderMethodWorker.call(TestMethodWithDataProviderMethodWorker.java:75)
	at org.testng.internal.TestMethodWithDataProviderMethodWorker.call(TestMethodWithDataProviderMethodWorker.java:14)
	at java.util.concurrent.FutureTask.run(Unknown Source)
	at java.util.concurrent.Executors$RunnableAdapter.call(Unknown Source)
	at java.util.concurrent.FutureTask.run(Unknown Source)
	at java.util.concurrent.ThreadPoolExecutor.runWorker(Unknown Source)
	at java.util.concurrent.ThreadPoolExecutor$Worker.run(Unknown Source)
	at java.lang.Thread.run(Unknown Source)
]]>
    </failure>
  </testcase> <!-- testB -->
</testsuite> <!-- Default test -->
